<?xml version="1.0"?>

<!--
Olly Smith & Sam White 2018

Loading in fusion360 parts to create a URDF model of the robot.

-->

<robot name="eduardo">

<!--
2.1.19
fixing the kinematics via a dummy base link
https://groups.google.com/forum/#!topic/moveit-users/kQXU5NYgOF8
-->

  <link name="base_footprint">
    <visual>
      <origin rpy="0 0 0" xyz="0 0 0"/>
      <geometry>
        <box size="0.001 0.001 0.001"/>
      </geometry>
    </visual>
  </link>

  <link name="base_link">
    <visual>
      <geometry>
        <mesh filename="file:/home/olly/ros_ws/src/sam/src/stls/07_Rail.stl" scale="0.001 0.001 0.001"/>
      </geometry>
      <origin rpy = "1.57 0 0" xyz = "0 0 0.04"/>
    </visual>
  </link>


  <joint name="base_footprint_joint" type="fixed">
    <origin rpy="0 0 0" xyz="0 0 0"/>
    <child link="base_link"/>
    <parent link="base_footprint"/>
  </joint>

  <link name="shoulder">
    <visual>
      <geometry>
        <mesh filename="file:/home/olly/ros_ws/src/sam/src/stls/06_GantryPlate.stl" scale="0.001 0.001 0.001"/>
      </geometry>
      <origin rpy = "1.57 0 0" xyz = "0 0 0.04"/>
    </visual>
  </link>

  <joint name="base_to_shoulder" type="prismatic">
    <axis xyz="1 0 0"/>
    <limit effort="1000" lower="-0.45" upper="0.45" velocity="0.1"/>
    <parent link="base_link"/>
    <child link="shoulder"/>
    <origin rpy = "0 0 0" xyz = "0 0 0"/>
  </joint>

  <link name="upper_arm">
    <visual>
      <geometry>
        <mesh filename="file:/home/olly/ros_ws/src/sam/src/stls/05_Upper Arm.stl" scale="0.001 0.001 0.001"/>
      </geometry>
      <origin rpy = "1.57 0 0" xyz = "0 0 0"/>
    </visual>
  </link>


  <joint name="shoulder_upper_arm" type="revolute">
    <axis xyz="0 0 1"/>
    <limit effort="1000" lower="-1" upper="1" velocity="0.1"/>
    <parent link="shoulder"/>
    <child link="upper_arm"/>
    <origin rpy = "0 0 0" xyz = "0 0.043 0"/>
  </joint>

  <link name="lower_arm">
    <visual>
      <geometry>
        <mesh filename="file:/home/olly/ros_ws/src/sam/src/stls/04_Forearm.stl" scale="0.001 0.001 0.001"/>
      </geometry>
      <origin rpy = "0 0 0" xyz = "0 0 0"/>
    </visual>
  </link>

  <joint name="upper_lower_arm" type="revolute">
    <axis xyz="0 0 1"/>
    <limit effort="1000" lower="0.3" upper="2.5" velocity="0.1"/>
    <parent link="upper_arm"/>
    <child link="lower_arm"/>
    <origin rpy = "1.0 1.57 0" xyz = "0.093 0.29 0.1377"/>
  </joint>



  <link name="comb_upper">
    <visual>
      <geometry>
        <mesh filename="file:/home/olly/ros_ws/src/sam/src/stls/03_Wrist Servo.stl" scale="0.001 0.001 0.001"/>
      </geometry>
      <origin rpy = "0 0 0" xyz = "0 0 0"/>
    </visual>
  </link>

  <joint name="lower_arm_hand" type="revolute">
    <axis xyz="0 0 1"/>
    <limit effort="1000" lower="-0.85" upper="1.6" velocity="0.1"/>
    <parent link="lower_arm"/>
    <child link="comb_upper"/>
    <origin rpy = "0 0 0" xyz = "0.108 -0.144 0"/>
  </joint>


  <link name="comb">
    <visual>
      <geometry>
        <mesh filename="file:/home/olly/ros_ws/src/sam/src/stls/02_End Effector Front.stl" scale="0.001 0.001 0.001"/>
      </geometry>
      <origin rpy = "0 0 0" xyz = "0 0 0"/>
    </visual>
  </link>

  <joint name="comb" type="revolute">
    <axis xyz="0 0 1"/>
    <limit effort="1000" lower="-1.6" upper="1.6" velocity="0.1"/>
    <parent link="comb_upper"/>
    <child link="comb"/>
    <origin rpy = "0 -1.57 0" xyz = "0.0224 -0.0195 0"/>
  </joint>


  <link name="comb_end">
    <visual>
      <geometry>
        <mesh filename="file:/home/olly/ros_ws/src/sam/src/stls/01_End Effector Top.stl" scale="0.001 0.001 0.001"/>
      </geometry>
      <origin rpy = "0 0 0" xyz = "0 0 0"/>
    </visual>
  </link>

  <joint name="comb_end" type="revolute">
    <axis xyz="0 0 1"/>
    <limit effort="1000" lower="0" upper="1.6" velocity="0.1"/>
    <parent link="comb"/>
    <child link="comb_end"/>
    <origin rpy = "0 1.57 0" xyz = "0.0032 -0.049387 -0.01975"/>
  </joint>











































</robot>

